<sdf version='1.3'>
  <world name='default'>
    <light name='sun' type='directional'>
      <cast_shadows>1</cast_shadows>
      <pose>0.000000 0.000000 10.000000 0.000000 0.000000 0.000000</pose>
      <diffuse>0.800000 0.800000 0.800000 1.000000</diffuse>
      <specular>0.100000 0.100000 0.100000 1.000000</specular>
      <attenuation>
        <range>1000.000000</range>
        <constant>0.900000</constant>
        <linear>0.010000</linear>
        <quadratic>0.001000</quadratic>
      </attenuation>
      <direction>-0.500000 0.500000 -1.000000</direction>
    </light>
    <model name='ground_plane'>
      <static>1</static>
      <link name='link'>
        <collision name='collision'>
          <geometry>
            <plane>
              <normal>0.000000 0.000000 1.000000</normal>
              <size>100.000000 100.000000</size>
            </plane>
          </geometry>
          <surface>
            <friction>
              <ode>
                <mu>100.000000</mu>
                <mu2>50.000000</mu2>
              </ode>
            </friction>
            <bounce/>
            <contact>
              <ode/>
            </contact>
          </surface>
        </collision>
        <visual name='visual'>
          <cast_shadows>0</cast_shadows>
          <geometry>
            <plane>
              <normal>0.000000 0.000000 1.000000</normal>
              <size>100.000000 100.000000</size>
            </plane>
          </geometry>
          <material>
            <script>
              <uri>file://media/materials/scripts/gazebo.material</uri>
              <name>Gazebo/Grey</name>
            </script>
          </material>
        </visual>
        <velocity_decay>
          <linear>0.000000</linear>
          <angular>0.000000</angular>
        </velocity_decay>
        <self_collide>0</self_collide>
        <kinematic>0</kinematic>
        <gravity>1</gravity>
      </link>
    </model>
    <physics type='ode'>
      <update_rate>1000.000000</update_rate>
      <gravity>0.000000 0.000000 -9.800000</gravity>
    </physics>
    <scene>
      <ambient>0.200000 0.200000 0.200000 1.000000</ambient>
      <background>0.700000 0.700000 0.700000 1.000000</background>
      <shadows>1</shadows>
    </scene>
    <model name='kitchen_gazebo'>
      <link name='base_link'>
        <pose>0.000000 0.000000 0.000000 0.000000 0.000000 0.000000</pose>
        <inertial>
          <pose>2.832790 4.836380 2.385820 0.000000 0.000000 0.000000</pose>
          <mass>24862.500000</mass>
          <inertia>
            <ixx>343870.000000</ixx>
            <ixy>-7565.990000</ixy>
            <ixz>-1978.630000</ixz>
            <iyy>227982.000000</iyy>
            <iyz>-3896.310000</iyz>
            <izz>474861.000000</izz>
          </inertia>
        </inertial>
        <collision name='base_link_geom'>
          <pose>0.000000 0.000000 0.000000 0.000000 0.000000 0.000000</pose>
          <geometry>
            <mesh>
              <scale>1.000000 1.000000 1.000000</scale>
              <uri>/home/cecilialiu/ros/kitchen_gazebo/meshes/base_link.STL</uri>
            </mesh>
          </geometry>
          <surface>
            <bounce/>
            <friction>
              <ode/>
            </friction>
            <contact>
              <ode/>
            </contact>
          </surface>
        </collision>
        <collision name='base_link_geom_counter_sink'>
          <pose>0.000000 0.000000 0.000000 0.000000 0.000000 0.000000</pose>
          <geometry>
            <mesh>
              <scale>1.000000 1.000000 1.000000</scale>
              <uri>/home/cecilialiu/ros/kitchen_gazebo/meshes/counter_sink.STL</uri>
            </mesh>
          </geometry>
          <surface>
            <bounce/>
            <friction>
              <ode/>
            </friction>
            <contact>
              <ode/>
            </contact>
          </surface>
        </collision>
        <collision name='base_link_geom_kitchen_counter'>
          <pose>0.000000 0.000000 0.000000 0.000000 0.000000 0.000000</pose>
          <geometry>
            <mesh>
              <scale>1.000000 1.000000 1.000000</scale>
              <uri>/home/cecilialiu/ros/kitchen_gazebo/meshes/kitchen_counter.STL</uri>
            </mesh>
          </geometry>
          <surface>
            <bounce/>
            <friction>
              <ode/>
            </friction>
            <contact>
              <ode/>
            </contact>
          </surface>
        </collision>
        <collision name='base_link_geom_water_pipe'>
          <pose>0.000000 0.000000 0.000000 0.000000 0.000000 0.000000</pose>
          <geometry>
            <mesh>
              <scale>1.000000 1.000000 1.000000</scale>
              <uri>/home/cecilialiu/ros/kitchen_gazebo/meshes/water_pipe.STL</uri>
            </mesh>
          </geometry>
          <surface>
            <bounce/>
            <friction>
              <ode/>
            </friction>
            <contact>
              <ode/>
            </contact>
          </surface>
        </collision>
        <visual name='base_link_visual'>
          <pose>0.000000 0.000000 0.000000 0.000000 0.000000 0.000000</pose>
          <geometry>
            <mesh>
              <scale>1.000000 1.000000 1.000000</scale>
              <uri>/home/cecilialiu/ros/kitchen_gazebo/meshes/base_link.STL</uri>
            </mesh>
          </geometry>
        </visual>
        <visual name='base_link_visualcounter_sink'>
          <pose>0.000000 0.000000 0.000000 0.000000 0.000000 0.000000</pose>
          <geometry>
            <mesh>
              <scale>1.000000 1.000000 1.000000</scale>
              <uri>/home/cecilialiu/ros/kitchen_gazebo/meshes/counter_sink.STL</uri>
            </mesh>
          </geometry>
        </visual>
        <visual name='base_link_visualkitchen_counter'>
          <pose>0.000000 0.000000 0.000000 0.000000 0.000000 0.000000</pose>
          <geometry>
            <mesh>
              <scale>1.000000 1.000000 1.000000</scale>
              <uri>/home/cecilialiu/ros/kitchen_gazebo/meshes/kitchen_counter.STL</uri>
            </mesh>
          </geometry>
        </visual>
        <visual name='base_link_visualwater_pipe'>
          <pose>0.000000 0.000000 0.000000 0.000000 0.000000 0.000000</pose>
          <geometry>
            <mesh>
              <scale>1.000000 1.000000 1.000000</scale>
              <uri>/home/cecilialiu/ros/kitchen_gazebo/meshes/water_pipe.STL</uri>
            </mesh>
          </geometry>
        </visual>
        <velocity_decay>
          <linear>0.000000</linear>
          <angular>0.000000</angular>
        </velocity_decay>
        <self_collide>0</self_collide>
        <kinematic>0</kinematic>
        <gravity>1</gravity>
      </link>
      <link name='drawer_left'>
        <pose>0.000000 0.000000 0.000000 0.000000 0.000000 0.000000</pose>
        <inertial>
          <pose>2.446800 1.637400 0.741348 0.000000 0.000000 0.000000</pose>
          <mass>9.477510</mass>
          <inertia>
            <ixx>0.315268</ixx>
            <ixy>-0.000000</ixy>
            <ixz>0.000192</ixz>
            <iyy>0.410596</iyy>
            <iyz>-0.000000</iyz>
            <izz>0.656397</izz>
          </inertia>
        </inertial>
        <collision name='drawer_left_geom'>
          <pose>0.000000 0.000000 0.000000 0.000000 0.000000 0.000000</pose>
          <geometry>
            <mesh>
              <scale>1.000000 1.000000 1.000000</scale>
              <uri>/home/cecilialiu/ros/kitchen_gazebo/meshes/drawer_left.STL</uri>
            </mesh>
          </geometry>
          <surface>
            <bounce/>
            <friction>
              <ode/>
            </friction>
            <contact>
              <ode/>
            </contact>
          </surface>
        </collision>
        <visual name='drawer_left_visual'>
          <pose>0.000000 0.000000 0.000000 0.000000 0.000000 0.000000</pose>
          <geometry>
            <mesh>
              <scale>1.000000 1.000000 1.000000</scale>
              <uri>/home/cecilialiu/ros/kitchen_gazebo/meshes/drawer_left.STL</uri>
            </mesh>
          </geometry>
        </visual>
        <velocity_decay>
          <linear>0.000000</linear>
          <angular>0.000000</angular>
        </velocity_decay>
        <self_collide>0</self_collide>
        <kinematic>0</kinematic>
        <gravity>1</gravity>
      </link>
      <joint name='drawer_left' type='prismatic'>
        <child>drawer_left</child>
        <parent>base_link</parent>
        <axis>
          <xyz>1.000000 0.000000 0.000000</xyz>
          <limit>
            <lower>0.000000</lower>
            <upper>0.550000</upper>
            <effort>1000.000000</effort>
            <velocity>0.500000</velocity>
          </limit>
          <dynamics/>
        </axis>
      </joint>
      <link name='drawer_right'>
        <pose>0.000000 0.000000 0.000000 0.000000 0.000000 0.000000</pose>
        <inertial>
          <pose>2.446800 2.137400 0.741348 0.000000 0.000000 0.000000</pose>
          <mass>9.477510</mass>
          <inertia>
            <ixx>0.315268</ixx>
            <ixy>-0.000000</ixy>
            <ixz>0.000192</ixz>
            <iyy>0.410596</iyy>
            <iyz>-0.000000</iyz>
            <izz>0.656397</izz>
          </inertia>
        </inertial>
        <collision name='drawer_right_geom'>
          <pose>0.000000 0.000000 0.000000 0.000000 0.000000 0.000000</pose>
          <geometry>
            <mesh>
              <scale>1.000000 1.000000 1.000000</scale>
              <uri>/home/cecilialiu/ros/kitchen_gazebo/meshes/drawer_right.STL</uri>
            </mesh>
          </geometry>
          <surface>
            <bounce/>
            <friction>
              <ode/>
            </friction>
            <contact>
              <ode/>
            </contact>
          </surface>
        </collision>
        <visual name='drawer_right_visual'>
          <pose>0.000000 0.000000 0.000000 0.000000 0.000000 0.000000</pose>
          <geometry>
            <mesh>
              <scale>1.000000 1.000000 1.000000</scale>
              <uri>/home/cecilialiu/ros/kitchen_gazebo/meshes/drawer_right.STL</uri>
            </mesh>
          </geometry>
        </visual>
        <velocity_decay>
          <linear>0.000000</linear>
          <angular>0.000000</angular>
        </velocity_decay>
        <self_collide>0</self_collide>
        <kinematic>0</kinematic>
        <gravity>1</gravity>
      </link>
      <joint name='drawer_right' type='prismatic'>
        <child>drawer_right</child>
        <parent>base_link</parent>
        <axis>
          <xyz>1.000000 0.000000 0.000000</xyz>
          <limit>
            <lower>0.000000</lower>
            <upper>0.550000</upper>
            <effort>1000.000000</effort>
            <velocity>0.500000</velocity>
          </limit>
          <dynamics/>
        </axis>
      </joint>
      <pose>0.000000 0.000000 0.000000 0.000000 0.000000 0.000000</pose>
      <static>0</static>
    </model>
    <state world_name='default'>
      <sim_time>0 0</sim_time>
      <real_time>0 0</real_time>
      <wall_time>1406137415 91584652</wall_time>
    </state>
    <gui fullscreen='0'>
      <camera name='user_camera'>
        <pose>5.000000 -5.000000 2.000000 0.000000 0.275643 2.356190</pose>
        <view_controller>orbit</view_controller>
      </camera>
    </gui>
  </world>
</sdf>
